[2025-07-02 19:25:22] Traceback (most recent call last):
[2025-07-02 19:25:22]   File "/app/bot.py", line 37, in <module>
[2025-07-02 19:25:22]     from cogs.draft_prob import DraftLotteryCog
[2025-07-02 19:25:22]   File "/app/cogs/draft_prob.py", line 1676
[2025-07-02 19:25:22]     "export_timestamp": datetime.now().isoformat(),
[2025-07-02 19:25:22] IndentationError: unexpected indent
[2025-07-02 19:25:20] ERROR failed health checks after 7 attempts with error Readiness probe failed: dial tcp 10.244.93.64:8080: connect: connection refused
[2025-07-02 19:25:50] ERROR component terminated with non-zero exit code: 1,
[]